Workbook
Name ASSET: [1]REF!#REF!
Name ASSET: REF!#REF!
Name RASCUNHO: 'RASCUNHO LP_IP_HP'!$A:$L
Name RASCUNHO: 'RASCUNHO LP_IP_HP'!$A:$L

Sheet Matriz

Sheet TEMPLATE MODEC
A1: Equipamento | B1: Atributos | D1: Tags PRIO | E1: Descrição PRIO | F1: H | G1: HH | H1: L | I1: LL | J1: unity
B2: Axial Displacement - Gear Box (1) | C2: ZT-1101 | D2: ZT-1101A | E2: G.B. shaft - axial displacement probe | F2: 0.1 | G2: 0.2 | H2: 0 | I2: 0 | J2: mm
B3: Axial Displacement - Gear Box (2) | C3: ZT-1101 | D3: ZT-1101B | E3: G.B. shaft - axial displacement probe | F3: 0.1 | G3: 0.2 | H3: 0 | I3: 0 | J3: mm
B4: Delta Pressure - Air Inlet Pre-Filter | C4: PDIT-1177 | D4: PDIT-1177 | E4: Turb. Inlet air pre-filter diff.press. transmitter | F4: 250 | G4: 0 | H4: 0 | I4: 0 | J4: Pa
B5: Keyphasor - Power Turbine (2) | C5: SE-1102 | D5: SE-1102B | E5: Power turbine speed B | F5: #N/A | G5: #N/A | H5: #N/A | I5: #N/A | J5: Rpm
B6: Level - Fuel scrubber level | C6: LIT-1103 | D6: LIT-1103 | E6: Fuel gas scrubber 1 level A transmitter | F6: 75 | G6: 0 | H6: 25 | I6: 0 | J6: %
B7: Pressure - Turbine Lube Oil Supply (b) | C7: PIT-1149 | D7: PIT-1149B | E7: Synthetic lube oil supply pressure B transmitter | F7: 0 | G7: 0 | H7: 172 | I7: 103 | J7: kpa
B8: Resistance - Sump Accessory Gearbox Magnectic Chip (2) | C8: QE-1101 | D8: QE-1101 | E8: Accessory gear box chip detector B sensor | F8: 100 | G8: 0 | H8: 0 | I8: 0 | J8: Ohm
B9: Temperature - Generator Cooling Water Return | C9: TE-1136 | D9: TE-1136 | E9: generator cooling water supply temp | F9: 38 | G9: 48 | H9: 0 | I9: 0 | J9: °F
B10: Temperature - Generator Cooling Water Supply | C10: TE-1137 | D10: TE-1137 | E10: generator cooling water return temp | F10: 49 | G10: 53 | H10: 0 | I10: 0 | J10: °F
B11: Temperature - PT Exhaust A | C11: TE-1112 | D11: TE-1112A | E11: PT exhaust duct temperature sensor A | F11: 570 | G11: 595 | H11: 0 | I11: 0 | J11: °C
B12: Temperature - PT Exhaust B | C12: TE-1112 | D12: TE-1112B | E12: PT exhaust duct temperature sensor B | F12: 570 | G12: 595 | H12: 0 | I12: 0 | J12: °C
B13: Temperature - PT Exhaust C | C13: TE-1112 | D13: TE-1112C | E13: PT exhaust duct temperature sensor C | F13: 570 | G13: 595 | H13: 0 | I13: 0 | J13: °C
B14: Temperature - PT Exhaust D | C14: TE-1112 | D14: TE-1112D | E14: PT exhaust duct temperature sensor D | F14: 570 | G14: 595 | H14: 0 | I14: 0 | J14: °C
B15: Temperature - PT Exhaust E | C15: TE-1112 | D15: TE-1112E | E15: PT exhaust duct temperature sensor E | F15: 570 | G15: 595 | H15: 0 | I15: 0 | J15: °C
B16: Temperature - PT Exhaust F | C16: TE-1112 | D16: TE-1112F | E16: PT exhaust duct temperature sensor F | F16: 570 | G16: 595 | H16: 0 | I16: 0 | J16: °F
B17: Temperature - Turbine Enclosure Exhaust A | C17: TE-1173 | D17: TE-1173A | E17: Turbine compartment outlet temperature A sensor | F17: 85 | G17: 90 | H17: 0 | I17: 0 | J17: °F
... B22: Temperature - Turbine Inlet (T48K) | C22: TE-1111 | D22: TE-1111K | E22: T48 sensor input from sensor K | F22: 843 | G22: 855 | H22: 0 | I22: 0 | J22: °C
B23: Vibration - Comp Rear Frame Velocity | C23: VE-1101 | D23: VE-1101 | E23: Compressor rear frame accelerometer | F23: #N/A | G23: #N/A | H23: #N/A | I23: #N/A | J23: mm/s
B24: Vibration - Gear Shaft HS Bearing (1) | C24: XT-1106 | D24: XT-1106X | E24: Gearbox high speed shaft journal brg X proximiter | F24: 63.5 | G24: 102 | H24: 0 | I24: 0 | J24: micron
B25: Vibration - Gear Shaft HS Bearing (2) | C25: XT-1106 | D25: XT-1106Y | E25: Gearbox high speed shaft journal brg Y proximiter | F25: 63.5 | G25: 102 | H25: 0 | I25: 0 | J25: micron
B26: Vibration - Gear Shaft HS Bearing (3) | C26: XT-1107 | D26: XT-1107X | E26: Gearbox high speed shaft journal brg X proximiter | F26: 63.5 | G26: 102 | H26: 0 | I26: 0 | J26: micron
B27: Vibration - Gear Shaft HS Bearing (4) | C27: XT-1107 | D27: XT-1107Y | E27: Gearbox high speed shaft journal brg Y proximiter | F27: 63.5 | G27: 102 | H27: 0 | I27: 0 | J27: micron
B28: Vibration - Gear Shaft LS Bearing (1) | C28: XT-1108 | D28: XT-1108X | E28: Gearbox low speed shaft journal brg X proximiter | F28: 88.9 | G28: 102 | H28: 0 | I28: 0 | J28: micron
B29: Vibration - Gear Shaft LS Bearing (2) | C29: XT-1108 | D29: XT-1108Y | E29: Gearbox low speed shaft journal brg Y proximiter | F29: 88.9 | G29: 102 | H29: 0 | I29: 0 | J29: micron
B30: Vibration - Gear Shaft LS Bearing (3) | C30: XT-1109 | D30: XT-1109X | E30: Gearbox low speed shaft journal brg X proximiter | F30: 88.9 | G30: 102 | H30: 0 | I30: 0 | J30: micron
B31: Vibration - Gear Shaft LS Bearing (4) | C31: XT-1109 | D31: XT-1109Y | E31: Gearbox low speed shaft journal brg Y proximiter | F31: 88.9 | G31: 102 | H31: 0 | I31: 0 | J31: micron
B32: Vibration - Gear Shaft Velocity (1) | C32: VE-1114 | D32: VE-1114 | E32: Gearbox velocity transducer detectors | F32: 0 | G32: 0 | H32: 0 | I32: 0 | J32: G
B33: Vibration - Gear Shaft Velocity (2) | C33: VE-1115 | D33: VE-1115 | E33: Gearbox velocity transducer detectors | F33: 0 | G33: 0 | H33: 0 | I33: 0 | J33: G
B34: Vibration - Generator DE Bearing | C34: VE-1116 | D34: VE-1116 | E34: Generator DE accelerometer monitoring detector | F34: 4.5 | G34: 7.1 | H34: 0 | I34: 0 | J34: Hz
B35: Vibration - Generator NDE Bearing | C35: VE-1117 | D35: VE-1117 | E35: Generator NDE accelerometer monitoring detector | F35: 4.5 | G35: 7.1 | H35: 0 | I35: 0 | J35: Hz
B36: Vibration - Turbine Rotor | C36: VE-1102 | D36: VE-1102 | E36: Power turbine rotor vibration detector | F36: 1905 | G36: 31.7 | H36: 0 | I36: 0 | J36: mm/s
B37: CO2e Emission | F37: #N/A | G37: #N/A | H37: #N/A | I37: #N/A | J37: #N/A
B38: CO2e Emission - Daily | F38: #N/A | G38: #N/A | H38: #N/A | I38: #N/A | J38: #N/A
B39: CO2e Emission - Daily|Natural Gas | F39: #N/A | G39: #N/A | H39: #N/A | I39: #N/A | J39: #N/A
B40: CO2e Emission - Totalizer | F40: #N/A | G40: #N/A | H40: #N/A | I40: #N/A | J40: #N/A
B41: Current - Exciter Field | F41: #N/A | G41: #N/A | H41: #N/A | I41: #N/A | J41: #N/A
B42: Current - L1 | F42: #N/A | G42: #N/A | H42: #N/A | I42: #N/A | J42: #N/A
B43: Current - L2 | F43: #N/A | G43: #N/A | H43: #N/A | I43: #N/A | J43: #N/A
B44: Current - L3 | F44: #N/A | G44: #N/A | H44: #N/A | I44: #N/A | J44: #N/A
...

Sheet FLASH GAS COMPRESSOR
A1: Name (EN) | B1: Nome (PT) | C1: Nome (PT)2 | D1: Disponível Frade Flash Gas Compressor | E1: ObjectType | F1: AttributeDefaultUOM | G1: AttributeType | H1: AttributeDataReference | I1: BaseTemplate | J1: Categories | K1: Categorias PT
A2: Acceleration - Compressor Casing (1) | B2: Aceleração - Carcaça do Compressor (1) | C2: Aceleração - Carcaça do Compressor (1) | D2: Não | E2: AttributeTemplate | G2: Double | H2: PI Point | J2: Sensors - Equipment Parts; | K2: Sensores - Componentes do Compressor
A3: Acceleration - Compressor Casing (2) | B3: Aceleração - Carcaça do Compressor (2) | C3: Aceleração - Carcaça do Compressor (2) | D3: Não | E3: AttributeTemplate | G3: Double | H3: PI Point | J3: Sensors - Equipment Parts; | K3: Sensores - Componentes do Compressor
A4: Current | B4: Corrente | C4: Corrente | D4: Não | E4: AttributeTemplate | F4: A | G4: Double | J4: Sensors - Electric Motor; | K4: Sensores - Motor Elétrico
A5: Delta Pressure - Primary Seal Gas Injection Discharge | B5: Delta de Pressão - Injeção de Gás de Vedação Primária Descarga | C5: Delta de Pressão - Injeção de Gás de Selagem Primária Descarga | D5: Não | E5: AttributeTemplate | G5: Double | J5: Sensors - Gas Seal System; | K5: Sensores - Sistema de Selagem a Gás
A6: Delta Pressure - Primary Seal Gas Injection Discharge (2) | B6: Delta de Pressão - Injeção de Gás de Vedação Primária Descarga (2) | C6: Delta de Pressão - Injeção de Gás de Selagem Primária Descarga (2) | D6: Não | E6: AttributeTemplate | G6: Double | J6: Sensors - Gas Seal System; | K6: Sensores - Sistema de Selagem a Gás
A7: Delta Pressure - Primary Seal Gas Injection Discharge (3) | B7: Delta de Pressão - Injeção de Gás de Vedação Primária Descarga (3) | C7: Delta de Pressão - Injeção de Gás de Selagem Primária Descarga (3) | D7: Não | E7: AttributeTemplate | G7: Double | J7: Sensors - Gas Seal System; | K7: Sensores - Sistema de Selagem a Gás
A8: Delta Pressure - Lube Oil Tank | B8: Delta de Pressão - Tanque de Óleo Lubrificante | C8: Delta de Pressão - Tanque de Óleo Lubrificante | D8: Não | E8: AttributeTemplate | G8: Double | J8: Sensors - Lube Oil System; | K8: Sensores - Sistema de Lubrificação
A9: Axial Displacement - Comp Female (2) | B9: Deslocamento Axial - Compressor Fêmea (2) | C9: Deslocamento Axial - Compressor Fêmea (2) | D9: Não | E9: AttributeTemplate | F9: µm | G9: Double | H9: PI Point | J9: Sensors - Equipment Parts; | K9: Sensores - Componentes do Compressor
A10: Axial Displacement - Comp Male (2) | B10: Deslocamento Axial - Compressor Macho (2) | C10: Deslocamento Axial - Compressor Macho (2) | D10: Não | E10: AttributeTemplate | F10: µm | G10: Double | H10: PI Point | J10: Sensors - Equipment Parts; | K10: Sensores - Componentes do Compressor
A11: Frequency - Motor | B11: Frequência - Motor | C11: Frequência - Motor | D11: Não | E11: AttributeTemplate | F11: Hz | G11: Double | J11: Sensors - Electric Motor; | K11: Sensores - Motor Elétrico
A12: Keyphasor - Comp Female | B12: Keyphasor - Compressor Fêmea | C12: Keyphasor - Compressor Fêmea | D12: Não | E12: AttributeTemplate | G12: Double | J12: Sensors - Equipment Parts; | K12: Sensores - Componentes do Compressor
A13: Keyphasor - Gear Shaft (2) | B13: Keyphasor - Eixo da Engrenagem (2) | C13: Keyphasor - Eixo da Engrenagem (2) | D13: Não | E13: AttributeTemplate | G13: Double | J13: Sensors - Gearbox; | K13: Sensores - Caixa de Engrenagens
A14: Pressure - Primary Seal Gas Injection Discharge (2) | B14: Pressão - Descarga de Injeção de Gás de Vedação Primária (2) | C14: Pressão - Descarga de Injeção de Gás de Selagem Primária (2) | D14: Não | E14: AttributeTemplate | G14: Double | J14: Sensors - Gas Seal System; | K14: Sensores - Sistema de Selagem a Gás
A15: Pressure - Process Gas Downstream Scrubber (2) | B15: Pressão - Gás de Processo a Jusante do Scrubber (2) | C15: Pressão - Gás de Processo a Jusante do Scrubber (2) | D15: Não | E15: AttributeTemplate | F15: barg | G15: Double | J15: Sensors - Scrubber; | K15: Sensores - Lavador de Gases
A16: Pressure - Process Gas Downstream Scrubber (3) | B16: Pressão - Gás de Processo a Jusante do Scrubber (3) | C16: Pressão - Gás de Processo a Jusante do Scrubber (3) | D16: Não | E16: AttributeTemplate | F16: barg | G16: Double | J16: Sensors - Scrubber; | K16: Sensores - Lavador de Gases
A17: Pressure - Lube Oil Simulation Line | B17: Pressão - Linha de Simulação de Óleo Lubrificante | C17: Pressão - Linha de Simulação de Óleo Lubrificante | D17: Não | E17: AttributeTemplate | G17: Double | J17: Sensors - Lube Oil System; | K17: Sensores - Sistema de Lubrificação
A18: Pressure - Lube Oil Supply Header (2) | B18: Pressão - Linha Principal de Suprimento de Óleo Lubrificante (2) | C18: Pressão - Linha Principal de Suprimento de Óleo Lubrificante (2) | D18: Não | E18: AttributeTemplate | G18: Double | J18: Sensors - Lube Oil System; | K18: Sensores - Sistema de Lubrificação
A19: Pressure - Lube Oil Supply Header (3) | B19: Pressão - Linha Principal de Suprimento de Óleo Lubrificante (3) | C19: Pressão - Linha Principal de Suprimento de Óleo Lubrificante (3) | D19: Não | E19: AttributeTemplate | G19: Double | J19: Sensors - Lube Oil System; | K19: Sensores - Sistema de Lubrificação
A20: Pressure - Primary Seal Gas Injection Suction (2) | B20: Pressão - Sucção de Injeção de Gás de Vedação Primária (2) | C20: Pressão - Sucção de Injeção de Gás de Selagem Primária (2) | D20: Não | E20: AttributeTemplate | G20: Double | J20: Sensors - Gas Seal System; | K20: Sensores - Sistema de Selagem a Gás
A21: Pressure - Primary Seal Gas Injection Suction (3) | B21: Pressão - Sucção de Injeção de Gás de Vedação Primária (3) | C21: Pressão - Sucção de Injeção de Gás de Selagem Primária (3) | D21: Não | E21: AttributeTemplate | G21: Double | J21: Sensors - Gas Seal System; | K21: Sensores - Sistema de Selagem a Gás
A22: Pressure - Primary Seal Gas Injection Suction (4) | B22: Pressão - Sucção de Injeção de Gás de Vedação Primária (4) | C22: Pressão - Sucção de Injeção de Gás de Selagem Primária (4) | D22: Não | E22: AttributeTemplate | G22: Double | J22: Sensors - Gas Seal System; | K22: Sensores - Sistema de Selagem a Gás
A23: Pressure - Primary Seal Leakage to Flare Male Discharge (2) | B23: Pressão - Vazamento da Vedação Primária para Flare Descarga Macho (2) | C23: Pressão - Vazamento da Selagem Primária para Flare Descarga Macho (2) | D23: Não | E23: AttributeTemplate | G23: Double | J23: Sensors - Gas Seal System; | K23: Sensores - Sistema de Selagem a Gás
A24: Pressure - Primary Seal Leakage to Flare Male Discharge (3) | B24: Pressão - Vazamento da Vedação Primária para Flare Descarga Macho (3) | C24: Pressão - Vazamento da Selagem Primária para Flare Descarga Macho (3) | D24: Não | E24: AttributeTemplate | G24: Double | J24: Sensors - Gas Seal System; | K24: Sensores - Sistema de Selagem a Gás
A25: Pressure - Primary Seal Leakage to Flare Male Discharge (4) | B25: Pressão - Vazamento da Vedação Primária para Flare Descarga Macho (4) | C25: Pressão - Vazamento da Selagem Primária para Flare Descarga Macho (4) | D25: Não | E25: AttributeTemplate | G25: Double | J25: Sensors - Gas Seal System; | K25: Sensores - Sistema de Selagem a Gás
A26: Pressure - Primary Seal Leakage to Flare Male Discharge (5) | B26: Pressão - Vazamento da Vedação Primária para Flare Descarga Macho (5) | C26: Pressão - Vazamento da Selagem Primária para Flare Descarga Macho (5) | D26: Não | E26: AttributeTemplate | G26: Double | J26: Sensors - Gas Seal System; | K26: Sensores - Sistema de Selagem a Gás
A27: Pressure - Primary Seal Leakage to Flare Female Suction (2) | B27: Pressão - Vazamento da Vedação Primária para Flare Sução Fêmea (2) | C27: Pressão - Vazamento da Selagem Primária para Flare Sução Fêmea (2) | D27: Não | E27: AttributeTemplate | G27: Double | J27: Sensors - Gas Seal System; | K27: Sensores - Sistema de Selagem a Gás
A28: Pressure - Primary Seal Leakage to Flare Female Suction (3) | B28: Pressão - Vazamento da Vedação Primária para Flare Sução Fêmea (3) | C28: Pressão - Vazamento da Selagem Primária para Flare Sução Fêmea (3) | D28: Não | E28: AttributeTemplate | G28: Double | J28: Sensors - Gas Seal System; | K28: Sensores - Sistema de Selagem a Gás
... A31: Temperature - Secondary Seal Gas Heater (2) | B31: Temperatura - Aquecedor de Gás de Vedação Secundária (2) | C31: Temperatura - Aquecedor de Gás de Selagem Secundária (2) | D31: Não | E31: AttributeTemplate | G31: Double | J31: Sensors - Gas Seal System; | K31: Sensores - Sistema de Selagem a Gás
A32: Temperature - Discharge (2) | B32: Temperatura - Descarga (2) | C32: Temperatura - Descarga (2) | D32: Não | E32: AttributeTemplate | F32: °C | G32: Double | J32: Sensors - Process Variables; | K32: Sensores - Variáveis de Processo
A33: Temperature - Comp Female Discharge Bearing (2) | B33: Temperatura - Mancal de Descarga do Compressor Fêmea (2) | C33: Temperatura - Mancal de Descarga do Compressor Fêmea (2) | D33: Não | E33: AttributeTemplate | G33: Double | J33: Sensors - Equipment Parts; | K33: Sensores - Componentes do Compressor
A34: Temperature - Comp Male Discharge Bearing (2) | B34: Temperatura - Mancal de Descarga do Compressor Macho (2) | C34: Temperatura - Mancal de Descarga do Compressor Macho (2) | D34: Não | E34: AttributeTemplate | G34: Double | J34: Sensors - Equipment Parts; | K34: Sensores - Componentes do Compressor
A35: Temperature - Comp Female Suction Bearing (2) | B35: Temperatura - Mancal de Sucção do Compressor Fêmea (2) | C35: Temperatura - Mancal de Sucção do Compressor Fêmea (2) | D35: Não | E35: AttributeTemplate | G35: Double | J35: Sensors - Equipment Parts; | K35: Sensores - Componentes do Compressor
A36: Temperature - Comp Male Suction Bearing (2) | B36: Temperatura - Mancal de Sucção do Compressor Macho (2) | C36: Temperatura - Mancal de Sucção do Compressor Macho (2) | D36: Não | E36: AttributeTemplate | G36: Double | J36: Sensors - Equipment Parts; | K36: Sensores - Componentes do Compressor
A37: Temperature - Lube Oil Downstream Filter | B37: Temperatura - Óleo Lubrificante a Jusante do Filtro | C37: Temperatura - Óleo Lubrificante a Jusante do Filtro | D37: Não | E37: AttributeTemplate | G37: Double | J37: Sensors - Lube Oil System; | K37: Sensores - Sistema de Lubrificação
A38: Temperature - Comp Lube Oil Return Discharge Side | B38: Temperatura - Retorno de Óleo Lubrificante do Compressor Lado Descarga | C38: Temperatura - Retorno de Óleo Lubrificante do Compressor Lado Descarga | D38: Não | E38: AttributeTemplate | G38: Double | J38: Sensors - Lube Oil System; | K38: Sensores - Sistema de Lubrificação
A39: Temperature - Comp Lube Oil Return Suction Side | B39: Temperatura - Retorno de Óleo Lubrificante do Compressor Lado Sucção | C39: Temperatura - Retorno de Óleo Lubrificante do Compressor Lado Sucção | D39: Não | E39: AttributeTemplate | G39: Double | J39: Sensors - Lube Oil System; | K39: Sensores - Sistema de Lubrificação
A40: Temperature - Motor Lube Oil Return DE | B40: Temperatura - Retorno de Óleo Lubrificante do Motor DE | C40: Temperatura - Retorno de Óleo Lubrificante do Motor (LA) | D40: Não | E40: AttributeTemplate | G40: Double | J40: Sensors - Lube Oil System; | K40: Sensores - Sistema de Lubrificação
A41: Temperature - Motor Lube Oil Return NDE | B41: Temperatura - Retorno de Óleo Lubrificante do Motor NDE | C41: Temperatura - Retorno de Óleo Lubrificante do Motor (LOA) | D41: Não | E41: AttributeTemplate | G41: Double | J41: Sensors - Lube Oil System; | K41: Sensores - Sistema de Lubrificação
A42: Temperature - Seal Gas Supply Heater Downstream | B42: Temperatura - Suprimento de Gás de Vedação à Jusante do Aquecedor | C42: Temperatura - Suprimento de Gás de Selagem à Jusante do Aquecedor | D42: Não | E42: AttributeTemplate | G42: Double | J42: Sensors - Gas Seal System; | K42: Sensores - Sistema de Selagem a Gás
...

Sheet RASCUNHO LP_IP_HP
A1: Parent | B1: Asset | C1: Name | D1: Value 2 | E1: Name Limiares | F1: Value | G1: UM | H1: Categories | I1: Categories 2 | J1: Notes | K1: Value2 | L1: Limiares2
A2: Compressor Basic | C2: Delta Pressure - ESDVs at the Scrubber Scution Pipe | D2: =_xlfn.REGEXREPLACE(F2, ".*-([A-Za-z]+)-([A-Za-z0-9]+).*", "$1$2") | E2: =IFERROR(TRIM(INDEX(_xlfn.TEXTSPLIT(Table3[[#This Row],[Name]],"|"),1,2)),"") | H2: Sensors - Scrubber; | I2: Sensors - Scrubber; | L2: =IFERROR(TRIM(INDEX(_xlfn.TEXTSPLIT(Table3[[#This Row],[Name]],"|"),1,2)),"") | Y2: Nível - Tanque de Óleo Lubrificante (1)|Hi | AA2: %
A3: Compressor Basic | C3: Delta Pressure - ESDVs at the Scrubber Scution Pipe|Pre-alarm | D3: =_xlfn.REGEXREPLACE(F3, ".*-([A-Za-z]+)-([A-Za-z0-9]+).*", "$1$2") | E3: =IFERROR(TRIM(INDEX(_xlfn.TEXTSPLIT(Table3[[#This Row],[Name]],"|"),1,2)),"") -> Pre-alarm | I3: Sensors - Scrubber; | L3: =IFERROR(TRIM(INDEX(_xlfn.TEXTSPLIT(Table3[[#This Row],[Name]],"|"),1,2)),"") -> Pre-alarm | Y3: Nível - Tanque de Óleo Lubrificante (1)|HiHi | AA3: %
A4: Compressor Basic | B4: FRADE-CAE-1340 & 1345 (LP/IP COMPRESSOR TRAIN 1) | C4: Delta Pressure - Lube Oil Filter | D4: =_xlfn.REGEXREPLACE(F4, ".*-([A-Za-z]+)-([A-Za-z0-9]+).*", "$1$2") -> PDI1222 | E4: =IFERROR(TRIM(INDEX(_xlfn.TEXTSPLIT(Table3[[#This Row],[Name]],"|"),1,2)),"") | F4: FRTS-072-PDI-1222 | G4: bar | H4: Sensors - Lube Oil System; | I4: Sensors - Lube Oil System; | K4: FRTS-072-PDI-1222 | L4: =IFERROR(TRIM(INDEX(_xlfn.TEXTSPLIT(Table3[[#This Row],[Name]],"|"),1,2)),"") | Y4: Nível - Tanque de Óleo Lubrificante (1)|Lo | AA4: %
A5: Compressor Basic | B5: FRADE-CAE-1340 & 1345 (LP/IP COMPRESSOR TRAIN 1) | C5: Delta Pressure - Lube Oil Filter|Hi | D5: =_xlfn.REGEXREPLACE(F5, ".*-([A-Za-z]+)-([A-Za-z0-9]+).*", "$1$2") -> 1 | E5: =IFERROR(TRIM(INDEX(_xlfn.TEXTSPLIT(Table3[[#This Row],[Name]],"|"),1,2)),"") -> Hi | F5: 1 | G5: bar | I5: Sensors - Lube Oil System; | K5: FRTS-072-PDI-1222 | L5: =IFERROR(TRIM(INDEX(_xlfn.TEXTSPLIT(Table3[[#This Row],[Name]],"|"),1,2)),"") -> Hi | Y5: Nível - Tanque de Óleo Lubrificante (1)|Pré-alarme Hi | AA5: %
A6: Compressor Basic | B6: FRADE-CAE-1340 & 1345 (LP/IP COMPRESSOR TRAIN 1) | C6: Delta Pressure - Lube Oil Filter|HiHi | D6: =_xlfn.REGEXREPLACE(F6, ".*-([A-Za-z]+)-([A-Za-z0-9]+).*", "$1$2") | E6: =IFERROR(TRIM(INDEX(_xlfn.TEXTSPLIT(Table3[[#This Row],[Name]],"|"),1,2)),"") -> HiHi | G6: bar | I6: Sensors - Lube Oil System; | K6: FRTS-072-PDI-1222 | L6: =IFERROR(TRIM(INDEX(_xlfn.TEXTSPLIT(Table3[[#This Row],[Name]],"|"),1,2)),"") -> HiHi | Y6: Pressão - Linha Principal de Óleo Lubrificante dos Mancais (2)|Hi | AA6: barg
A7: Compressor Basic | B7: FRADE-CAE-1340 & 1345 (LP/IP COMPRESSOR TRAIN 1) | C7: Delta Pressure - Lube Oil Filter|Pre-alarm Hi | D7: =_xlfn.REGEXREPLACE(F7, ".*-([A-Za-z]+)-([A-Za-z0-9]+).*", "$1$2") | E7: =IFERROR(TRIM(INDEX(_xlfn.TEXTSPLIT(Table3[[#This Row],[Name]],"|"),1,2)),"") -> Pre-alarm Hi | G7: bar | I7: Sensors - Lube Oil System; | K7: FRTS-072-PDI-1222 | L7: =IFERROR(TRIM(INDEX(_xlfn.TEXTSPLIT(Table3[[#This Row],[Name]],"|"),1,2)),"") -> Pre-alarm Hi | Y7: Pressão - Linha Principal de Óleo Lubrificante dos Mancais (2)|Lo | AA7: barg
A8: Compressor Basic | C8: Delta Pressure - Lube Oil Reservoir Pressure to Atm | D8: =_xlfn.REGEXREPLACE(F8, ".*-([A-Za-z]+)-([A-Za-z0-9]+).*", "$1$2") | E8: =IFERROR(TRIM(INDEX(_xlfn.TEXTSPLIT(Table3[[#This Row],[Name]],"|"),1,2)),"") | H8: Sensors - Lube Oil System; | I8: Sensors - Lube Oil System; | L8: =IFERROR(TRIM(INDEX(_xlfn.TEXTSPLIT(Table3[[#This Row],[Name]],"|"),1,2)),"") | Y8: Pressão - Linha Principal de Óleo Lubrificante dos Mancais (2)|Pré-alarme Hi | AA8: barg
A9: Compressor Basic | C9: Delta Pressure - Lube Oil Reservoir Pressure to Atm|Hi | D9: =_xlfn.REGEXREPLACE(F9, ".*-([A-Za-z]+)-([A-Za-z0-9]+).*", "$1$2") | E9: =IFERROR(TRIM(INDEX(_xlfn.TEXTSPLIT(Table3[[#This Row],[Name]],"|"),1,2)),"") -> Hi | I9: Sensors - Lube Oil System; | L9: =IFERROR(TRIM(INDEX(_xlfn.TEXTSPLIT(Table3[[#This Row],[Name]],"|"),1,2)),"") -> Hi | Y9: Temperatura - Tanque de Óleo Lubrificante|Hi | Z9: 75 | AA9: °C
A10: Compressor Basic | C10: Delta Pressure - Lube Oil Reservoir Pressure to Atm|Lo | D10: =_xlfn.REGEXREPLACE(F10, ".*-([A-Za-z]+)-([A-Za-z0-9]+).*", "$1$2") | E10: =IFERROR(TRIM(INDEX(_xlfn.TEXTSPLIT(Table3[[#This Row],[Name]],"|"),1,2)),"") -> Lo | I10: Sensors - Lube Oil System; | L10: =IFERROR(TRIM(INDEX(_xlfn.TEXTSPLIT(Table3[[#This Row],[Name]],"|"),1,2)),"") -> Lo | Y10: Temperatura - Tanque de Óleo Lubrificante|HiHi | AA10: °C
A11: Compressor Basic | B11: FRADE-CAE-1340 & 1345 (LP/IP COMPRESSOR TRAIN 1) | C11: Level - Lube Oil Tank (1) | D11: =_xlfn.REGEXREPLACE(F11, ".*-([A-Za-z]+)-([A-Za-z0-9]+).*", "$1$2") -> LI1212A | E11: =IFERROR(TRIM(INDEX(_xlfn.TEXTSPLIT(Table3[[#This Row],[Name]],"|"),1,2)),"") | F11: FRTS-LI-1212A | G11: % | H11: Sensors - Lube Oil System; | I11: Sensors - Lube Oil System; | K11: FRTS-LI-1212A | L11: =IFERROR(TRIM(INDEX(_xlfn.TEXTSPLIT(Table3[[#This Row],[Name]],"|"),1,2)),"") | Y11: Temperatura - Tanque de Óleo Lubrificante|Lo | Z11: 30 | AA11: °C
A12: Compressor Basic | B12: FRADE-CAE-1340 & 1345 (LP/IP COMPRESSOR TRAIN 1) | C12: Level - Lube Oil Tank (1)|Hi | D12: =_xlfn.REGEXREPLACE(F12, ".*-([A-Za-z]+)-([A-Za-z0-9]+).*", "$1$2") | E12: =IFERROR(TRIM(INDEX(_xlfn.TEXTSPLIT(Table3[[#This Row],[Name]],"|"),1,2)),"") -> Hi | G12: % | I12: Sensors - Lube Oil System; | K12: FRTS-LI-1212A | L12: =IFERROR(TRIM(INDEX(_xlfn.TEXTSPLIT(Table3[[#This Row],[Name]],"|"),1,2)),"") -> Hi | Y12: Temperatura - Tanque de Óleo Lubrificante|Pré-alarme Hi | AA12: °C
A13: Compressor Basic | B13: FRADE-CAE-1340 & 1345 (LP/IP COMPRESSOR TRAIN 1) | C13: Level - Lube Oil Tank (1)|HiHi | D13: =_xlfn.REGEXREPLACE(F13, ".*-([A-Za-z]+)-([A-Za-z0-9]+).*", "$1$2") | E13: =IFERROR(TRIM(INDEX(_xlfn.TEXTSPLIT(Table3[[#This Row],[Name]],"|"),1,2)),"") -> HiHi | G13: % | I13: Sensors - Lube Oil System; | K13: FRTS-LI-1212A | L13: =IFERROR(TRIM(INDEX(_xlfn.TEXTSPLIT(Table3[[#This Row],[Name]],"|"),1,2)),"") -> HiHi | Y13: Temperatura - Mancal do Motor (LA)|Hi | Z13: 90 | AA13: °C
A14: Compressor Basic | B14: FRADE-CAE-1340 & 1345 (LP/IP COMPRESSOR TRAIN 1) | C14: Level - Lube Oil Tank (1)|Lo | D14: =_xlfn.REGEXREPLACE(F14, ".*-([A-Za-z]+)-([A-Za-z0-9]+).*", "$1$2") | E14: =IFERROR(TRIM(INDEX(_xlfn.TEXTSPLIT(Table3[[#This Row],[Name]],"|"),1,2)),"") -> Lo | G14: % | I14: Sensors - Lube Oil System; | K14: FRTS-LI-1212A | L14: =IFERROR(TRIM(INDEX(_xlfn.TEXTSPLIT(Table3[[#This Row],[Name]],"|"),1,2)),"") -> Lo | Y14: Temperatura - Mancal do Motor (LA)|HiHi | Z14: 95 | AA14: °C
A15: Compressor Basic | B15: FRADE-CAE-1340 & 1345 (LP/IP COMPRESSOR TRAIN 1) | C15: Level - Lube Oil Tank (1)|LoLo | D15: =_xlfn.REGEXREPLACE(F15, ".*-([A-Za-z]+)-([A-Za-z0-9]+).*", "$1$2") | E15: =IFERROR(TRIM(INDEX(_xlfn.TEXTSPLIT(Table3[[#This Row],[Name]],"|"),1,2)),"") -> LoLo | G15: % | I15: Sensors - Lube Oil System; | K15: FRTS-LI-1212A | L15: =IFERROR(TRIM(INDEX(_xlfn.TEXTSPLIT(Table3[[#This Row],[Name]],"|"),1,2)),"") -> LoLo | Y15: Temperatura - Mancal do Motor (LA)|Pré-alarme Hi | AA15: °C
A16: Compressor Basic | B16: FRADE-CAE-1340 & 1345 (LP/IP COMPRESSOR TRAIN 1) | C16: Level - Lube Oil Tank (1)|Pre-alarm Hi | D16: =_xlfn.REGEXREPLACE(F16, ".*-([A-Za-z]+)-([A-Za-z0-9]+).*", "$1$2") | E16: =IFERROR(TRIM(INDEX(_xlfn.TEXTSPLIT(Table3[[#This Row],[Name]],"|"),1,2)),"") -> Pre-alarm Hi | G16: % | I16: Sensors - Lube Oil System; | K16: FRTS-LI-1212A | L16: =IFERROR(TRIM(INDEX(_xlfn.TEXTSPLIT(Table3[[#This Row],[Name]],"|"),1,2)),"") -> Pre-alarm Hi | Y16: Temperatura - Mancal do Motor (LOA)|Hi | Z16: 90 | AA16: °C
A17: Compressor Basic | B17: FRADE-CAE-1340 & 1345 (LP/IP COMPRESSOR TRAIN 1) | C17: Level - Lube Oil Tank (1)|Pre-alarm Lo | D17: =_xlfn.REGEXREPLACE(F17, ".*-([A-Za-z]+)-([A-Za-z0-9]+).*", "$1$2") | E17: =IFERROR(TRIM(INDEX(_xlfn.TEXTSPLIT(Table3[[#This Row],[Name]],"|"),1,2)),"") -> Pre-alarm Lo | G17: % | I17: Sensors - Lube Oil System; | K17: FRTS-LI-1212A | L17: =IFERROR(TRIM(INDEX(_xlfn.TEXTSPLIT(Table3[[#This Row],[Name]],"|"),1,2)),"") -> Pre-alarm Lo | Y17: Temperatura - Mancal do Motor (LOA)|HiHi | Z17: 95 | AA17: °C
A18: Compressor Basic | B18: FRADE-CAE-1340 & 1345 (LP/IP COMPRESSOR TRAIN 1) | C18: Level - Lube Oil Tank (2) | D18: =_xlfn.REGEXREPLACE(F18, ".*-([A-Za-z]+)-([A-Za-z0-9]+).*", "$1$2") -> LI1212B | E18: =IFERROR(TRIM(INDEX(_xlfn.TEXTSPLIT(Table3[[#This Row],[Name]],"|"),1,2)),"") | F18: FRTS-071-LI-1212B | H18: Sensors - Lube Oil System; | I18: Sensors - Lube Oil System; | J18: Não encontrado no PI | K18: FRTS-LI-1212B | L18: =IFERROR(TRIM(INDEX(_xlfn.TEXTSPLIT(Table3[[#This Row],[Name]],"|"),1,2)),"") | Y18: Temperatura - Mancal do Motor (LOA)|Pré-alarme Hi | AA18: °C
A19: Compressor Basic | B19: FRADE-CAE-1340 & 1345 (LP/IP COMPRESSOR TRAIN 1) | C19: Level - Lube Oil Tank (2)|Hi | D19: =_xlfn.REGEXREPLACE(F19, ".*-([A-Za-z]+)-([A-Za-z0-9]+).*", "$1$2") | E19: =IFERROR(TRIM(INDEX(_xlfn.TEXTSPLIT(Table3[[#This Row],[Name]],"|"),1,2)),"") -> Hi | I19: Sensors - Lube Oil System; | K19: FRTS-LI-1212B | L19: =IFERROR(TRIM(INDEX(_xlfn.TEXTSPLIT(Table3[[#This Row],[Name]],"|"),1,2)),"") -> Hi | Y19: Temperatura - Ar Frio do Estator (1)|Hi | Z19: 55 | AA19: °C
A20: Compressor Basic | B20: FRADE-CAE-1340 & 1345 (LP/IP COMPRESSOR TRAIN 1) | C20: Level - Lube Oil Tank (2)|HiHi | D20: =_xlfn.REGEXREPLACE(F20, ".*-([A-Za-z]+)-([A-Za-z0-9]+).*", "$1$2") | E20: =IFERROR(TRIM(INDEX(_xlfn.TEXTSPLIT(Table3[[#This Row],[Name]],"|"),1,2)),"") -> HiHi | I20: Sensors - Lube Oil System; | K20: FRTS-LI-1212B | L20: =IFERROR(TRIM(INDEX(_xlfn.TEXTSPLIT(Table3[[#This Row],[Name]],"|"),1,2)),"") -> HiHi | Y20: Temperatura - Ar Frio do Estator (1)|HiHi | Z20: 60 | AA20: °C
A21: Compressor Basic | B21: FRADE-CAE-1340 & 1345 (LP/IP COMPRESSOR TRAIN 1) | C21: Level - Lube Oil Tank (2)|Lo | D21: =_xlfn.REGEXREPLACE(F21, ".*-([A-Za-z]+)-([A-Za-z0-9]+).*", "$1$2") | E21: =IFERROR(TRIM(INDEX(_xlfn.TEXTSPLIT(Table3[[#This Row],[Name]],"|"),1,2)),"") -> Lo | I21: Sensors - Lube Oil System; | K21: FRTS-LI-1212B | L21: =IFERROR(TRIM(INDEX(_xlfn.TEXTSPLIT(Table3[[#This Row],[Name]],"|"),1,2)),"") -> Lo | Y21: Temperatura - Ar Frio do Estator (1)|Pré-alarme Hi | AA21: °C
A22: Compressor Basic | B22: FRADE-CAE-1340 & 1345 (LP/IP COMPRESSOR TRAIN 1) | C22: Level - Lube Oil Tank (2)|LoLo | D22: =_xlfn.REGEXREPLACE(F22, ".*-([A-Za-z]+)-([A-Za-z0-9]+).*", "$1$2") | E22: =IFERROR(TRIM(INDEX(_xlfn.TEXTSPLIT(Table3[[#This Row],[Name]],"|"),1,2)),"") -> LoLo | I22: Sensors - Lube Oil System; | K22: FRTS-LI-1212B | L22: =IFERROR(TRIM(INDEX(_xlfn.TEXTSPLIT(Table3[[#This Row],[Name]],"|"),1,2)),"") -> LoLo | Y22: Temperatura - Ar Quente do Estator|Hi | Z22: 105 | AA22: °C
A23: Compressor Basic | B23: FRADE-CAE-1340 & 1345 (LP/IP COMPRESSOR TRAIN 1) | C23: Level - Lube Oil Tank (2)|Pre-alarm Hi | D23: =_xlfn.REGEXREPLACE(F23, ".*-([A-Za-z]+)-([A-Za-z0-9]+).*", "$1$2") | E23: =IFERROR(TRIM(INDEX(_xlfn.TEXTSPLIT(Table3[[#This Row],[Name]],"|"),1,2)),"") -> Pre-alarm Hi | I23: Sensors - Lube Oil System; | K23: FRTS-LI-1212B | L23: =IFERROR(TRIM(INDEX(_xlfn.TEXTSPLIT(Table3[[#This Row],[Name]],"|"),1,2)),"") -> Pre-alarm Hi | Y23: Temperatura - Ar Quente do Estator|HiHi | Z23: 110 | AA23: °C
A24: Compressor Basic | B24: FRADE-CAE-1340 & 1345 (LP/IP COMPRESSOR TRAIN 1) | C24: Level - Lube Oil Tank (2)|Pre-alarm Lo | D24: =_xlfn.REGEXREPLACE(F24, ".*-([A-Za-z]+)-([A-Za-z0-9]+).*", "$1$2") | E24: =IFERROR(TRIM(INDEX(_xlfn.TEXTSPLIT(Table3[[#This Row],[Name]],"|"),1,2)),"") -> Pre-alarm Lo | I24: Sensors - Lube Oil System; | K24: FRTS-LI-1212B | L24: =IFERROR(TRIM(INDEX(_xlfn.TEXTSPLIT(Table3[[#This Row],[Name]],"|"),1,2)),"") -> Pre-alarm Lo | Y24: Temperatura - Ar Quente do Estator|Pré-alarme Hi | AA24: °C
A25: Compressor Basic | B25: FRADE-CAE-1340 & 1345 (LP/IP COMPRESSOR TRAIN 1) | C25: Level - Rundown Tank | D25: =_xlfn.REGEXREPLACE(F25, ".*-([A-Za-z]+)-([A-Za-z0-9]+).*", "$1$2") -> LT1228 | E25: =IFERROR(TRIM(INDEX(_xlfn.TEXTSPLIT(Table3[[#This Row],[Name]],"|"),1,2)),"") | F25: FRTS-071-LT-1228 | H25: Sensors - Lube Oil System; | I25: Sensors - Lube Oil System; | J25: Não encontrado no PI | K25: LT1228 | L25: =IFERROR(TRIM(INDEX(_xlfn.TEXTSPLIT(Table3[[#This Row],[Name]],"|"),1,2)),"") | Y25: Temperatura - Estator Fase U|Hi | Z25: 140 | AA25: °C
A26: Compressor Basic | B26: FRADE-CAE-1340 & 1345 (LP/IP COMPRESSOR TRAIN 1) | C26: Level - Rundown Tank|Hi | D26: =_xlfn.REGEXREPLACE(F26, ".*-([A-Za-z]+)-([A-Za-z0-9]+).*", "$1$2") | E26: =IFERROR(TRIM(INDEX(_xlfn.TEXTSPLIT(Table3[[#This Row],[Name]],"|"),1,2)),"") -> Hi | I26: Sensors - Lube Oil System; | J26: Não encontrado no PI | K26: LT1228 | L26: =IFERROR(TRIM(INDEX(_xlfn.TEXTSPLIT(Table3[[#This Row],[Name]],"|"),1,2)),"") -> Hi | Y26: Temperatura - Estator Fase U|HiHi | Z26: 150 | AA26: °C
A27: Compressor Basic | B27: FRADE-CAE-1340 & 1345 (LP/IP COMPRESSOR TRAIN 1) | C27: Level - Rundown Tank|Lo | D27: =_xlfn.REGEXREPLACE(F27, ".*-([A-Za-z]+)-([A-Za-z0-9]+).*", "$1$2") | E27: =IFERROR(TRIM(INDEX(_xlfn.TEXTSPLIT(Table3[[#This Row],[Name]],"|"),1,2)),"") -> Lo | I27: Sensors - Lube Oil System; | J27: Não encontrado no PI | K27: LT1228 | L27: =IFERROR(TRIM(INDEX(_xlfn.TEXTSPLIT(Table3[[#This Row],[Name]],"|"),1,2)),"") -> Lo | Y27: Temperatura - Estator Fase U|Lo | AA27: °C
A28: Compressor Basic | B28: FRADE-CAE-1340 & 1345 (LP/IP COMPRESSOR TRAIN 1) | C28: Level - Rundown Tank|LoLo | D28: =_xlfn.REGEXREPLACE(F28, ".*-([A-Za-z]+)-([A-Za-z0-9]+).*", "$1$2") | E28: =IFERROR(TRIM(INDEX(_xlfn.TEXTSPLIT(Table3[[#This Row],[Name]],"|"),1,2)),"") -> LoLo | I28: Sensors - Lube Oil System; | J28: Não encontrado no PI | K28: LT1228 | L28: =IFERROR(TRIM(INDEX(_xlfn.TEXTSPLIT(Table3[[#This Row],[Name]],"|"),1,2)),"") -> LoLo | Y28: Temperatura - Estator Fase U|Pré-alarme Hi | AA28: °C
A29: Compressor Basic | B29: FRADE-CAE-1340 & 1345 (LP/IP COMPRESSOR TRAIN 1) | C29: Level - Rundown Tank|Pre-alarm Lo | D29: =_xlfn.REGEXREPLACE(F29, ".*-([A-Za-z]+)-([A-Za-z0-9]+).*", "$1$2") | E29: =IFERROR(TRIM(INDEX(_xlfn.TEXTSPLIT(Table3[[#This Row],[Name]],"|"),1,2)),"") -> Pre-alarm Lo | I29: Sensors - Lube Oil System; | J29: Não encontrado no PI | K29: LT1228 | L29: =IFERROR(TRIM(INDEX(_xlfn.TEXTSPLIT(Table3[[#This Row],[Name]],"|"),1,2)),"") -> Pre-alarm Lo | Y29: Temperatura - Estator Fase U (2)|Hi | Z29: 140 | AA29: °C
A30: Compressor Basic | C30: Level - Scrubber | D30: =_xlfn.REGEXREPLACE(F30, ".*-([A-Za-z]+)-([A-Za-z0-9]+).*", "$1$2") | E30: =IFERROR(TRIM(INDEX(_xlfn.TEXTSPLIT(Table3[[#This Row],[Name]],"|"),1,2)),"") | H30: Sensors - Scrubber; | I30: Sensors - Scrubber; | L30: =IFERROR(TRIM(INDEX(_xlfn.TEXTSPLIT(Table3[[#This Row],[Name]],"|"),1,2)),"") | Y30: Temperatura - Estator Fase U (2)|HiHi | Z30: 150 | AA30: °C
A31: Compressor Basic | C31: Level - Scrubber Control | D31: =_xlfn.REGEXREPLACE(F31, ".*-([A-Za-z]+)-([A-Za-z0-9]+).*", "$1$2") | E31: =IFERROR(TRIM(INDEX(_xlfn.TEXTSPLIT(Table3[[#This Row],[Name]],"|"),1,2)),"") | H31: Sensors - Scrubber; | I31: Sensors - Scrubber; | L31: =IFERROR(TRIM(INDEX(_xlfn.TEXTSPLIT(Table3[[#This Row],[Name]],"|"),1,2)),"") | Y31: Temperatura - Estator Fase U (2)|Lo | AA31: °C
A32: Compressor Basic | C32: Particle Count|Assay | D32: =_xlfn.REGEXREPLACE(F32, ".*-([A-Za-z]+)-([A-Za-z0-9]+).*", "$1$2") | E32: =IFERROR(TRIM(INDEX(_xlfn.TEXTSPLIT(Table3[[#This Row],[Name]],"|"),1,2)),"") -> Assay | I32: Sensors - Scrubber; | L32: =IFERROR(TRIM(INDEX(_xlfn.TEXTSPLIT(Table3[[#This Row],[Name]],"|"),1,2)),"") -> Assay | Y32: Temperatura - Estator Fase U (2)|Pré-alarme Hi | AA32: °C
A33: Compressor Basic | C33: Particle Count|Hi | D33: =_xlfn.REGEXREPLACE(F33, ".*-([A-Za-z]+)-([A-Za-z0-9]+).*", "$1$2") | E33: =IFERROR(TRIM(INDEX(_xlfn.TEXTSPLIT(Table3[[#This Row],[Name]],"|"),1,2)),"") -> Hi | I33: Sensors - Scrubber; | L33: =IFERROR(TRIM(INDEX(_xlfn.TEXTSPLIT(Table3[[#This Row],[Name]],"|"),1,2)),"") -> Hi | Y33: Temperatura - Estator Fase V|Hi | Z33: 140 | AA33: °C
A34: Compressor Basic | C34: Particle Count|Particle Count - String | D34: =_xlfn.REGEXREPLACE(F34, ".*-([A-Za-z]+)-([A-Za-z0-9]+).*", "$1$2") | E34: =IFERROR(TRIM(INDEX(_xlfn.TEXTSPLIT(Table3[[#This Row],[Name]],"|"),1,2)),"") -> Particle Count - String | I34: Sensors - Scrubber; | L34: =IFERROR(TRIM(INDEX(_xlfn.TEXTSPLIT(Table3[[#This Row],[Name]],"|"),1,2)),"") -> Particle Count - String | Y34: Temperatura - Estator Fase V|HiHi | Z34: 150 | AA34: °C
A35: Compressor Basic | C35: Particle Count|Particle Count - String|Replaced | D35: =_xlfn.REGEXREPLACE(F35, ".*-([A-Za-z]+)-([A-Za-z0-9]+).*", "$1$2") | E35: =IFERROR(TRIM(INDEX(_xlfn.TEXTSPLIT(Table3[[#This Row],[Name]],"|"),1,2)),"") -> Particle Count - String | I35: Sensors - Scrubber; | L35: =IFERROR(TRIM(INDEX(_xlfn.TEXTSPLIT(Table3[[#This Row],[Name]],"|"),1,2)),"") -> Particle Count - String | Y35: Temperatura - Estator Fase V|Lo | AA35: °C
A36: Compressor Basic | C36: Particle Count|Replaced | D36: =_xlfn.REGEXREPLACE(F36, ".*-([A-Za-z]+)-([A-Za-z0-9]+).*", "$1$2") | E36: =IFERROR(TRIM(INDEX(_xlfn.TEXTSPLIT(Table3[[#This Row],[Name]],"|"),1,2)),"") -> Replaced | I36: Sensors - Scrubber; | L36: =IFERROR(TRIM(INDEX(_xlfn.TEXTSPLIT(Table3[[#This Row],[Name]],"|"),1,2)),"") -> Replaced | Y36: Temperatura - Estator Fase V|Pré-alarme Hi | AA36: °C
A37: Compressor Basic | C37: Particle Count|Type | D37: =_xlfn.REGEXREPLACE(F37, ".*-([A-Za-z]+)-([A-Za-z0-9]+).*", "$1$2") | E37: =IFERROR(TRIM(INDEX(_xlfn.TEXTSPLIT(Table3[[#This Row],[Name]],"|"),1,2)),"") -> Type | I37: Sensors - Scrubber; | L37: =IFERROR(TRIM(INDEX(_xlfn.TEXTSPLIT(Table3[[#This Row],[Name]],"|"),1,2)),"") -> Type | Y37: Temperatura - Estator Fase V (2)|Hi | Z37: 140 | AA37: °C
A38: Compressor Basic | C38: Pressure - Lube Oil Auxiliary Pump Discharge | D38: =_xlfn.REGEXREPLACE(F38, ".*-([A-Za-z]+)-([A-Za-z0-9]+).*", "$1$2") | E38: =IFERROR(TRIM(INDEX(_xlfn.TEXTSPLIT(Table3[[#This Row],[Name]],"|"),1,2)),"") | H38: Sensors - Lube Oil System; | I38: Sensors - Lube Oil System; | L38: =IFERROR(TRIM(INDEX(_xlfn.TEXTSPLIT(Table3[[#This Row],[Name]],"|"),1,2)),"") | Y38: Temperatura - Estator Fase V (2)|HiHi | Z38: 150 | AA38: °C
A39: Compressor Basic | C39: Pressure - Lube Oil Auxiliary Pump Discharge|Hi | D39: =_xlfn.REGEXREPLACE(F39, ".*-([A-Za-z]+)-([A-Za-z0-9]+).*", "$1$2") | E39: =IFERROR(TRIM(INDEX(_xlfn.TEXTSPLIT(Table3[[#This Row],[Name]],"|"),1,2)),"") -> Hi | I39: Sensors - Lube Oil System; | L39: =IFERROR(TRIM(INDEX(_xlfn.TEXTSPLIT(Table3[[#This Row],[Name]],"|"),1,2)),"") -> Hi | Y39: Temperatura - Estator Fase V (2)|Lo | AA39: °C
A40: Compressor Basic | C40: Pressure - Lube Oil Auxiliary Pump Discharge|Lo | D40: =_xlfn.REGEXREPLACE(F40, ".*-([A-Za-z]+)-([A-Za-z0-9]+).*", "$1$2") | E40: =IFERROR(TRIM(INDEX(_xlfn.TEXTSPLIT(Table3[[#This Row],[Name]],"|"),1,2)),"") -> Lo | I40: Sensors - Lube Oil System; | L40: =IFERROR(TRIM(INDEX(_xlfn.TEXTSPLIT(Table3[[#This Row],[Name]],"|"),1,2)),"") -> Lo | Y40: Temperatura - Estator Fase V (2)|Pré-alarme Hi | AA40: °C
...

Sheet Sheet2
A1: Template | B1: Asset | C1: Name | E1: Limiares | F1: Tag | G1: UM | H1: Categorias | I1: Categorias 2 | J1: A | K1: B | L1: C
A2: Compressor Basic | B2: FRADE-PBA-1350 (HP Compressor Trem 1) | C2: Delta Pressure - Lube Oil Filter | D2: =_xlfn.CONCAT(B2,C2) -> FRADE-PBA-1350 (HP Compressor Trem 1)Delta Pressure - Lube Oil Filter | E2: =IFERROR(TRIM(INDEX(_xlfn.TEXTSPLIT(Table3[[#This Row],[Name]],"|"),1,2)),"") | F2: =VLOOKUP(D2,REF!$AA$1:$AB$149,2,0) -> FRTS-072-PDI-1422 | G2: bar | H2: Sensors - Lube Oil System; | I2: Sensors - Lube Oil System; | L2: =IFERROR(TRIM(INDEX(_xlfn.TEXTSPLIT(Table3[[#This Row],[Name]],"|"),1,2)),"")
A3: Compressor Basic | B3: FRADE-PBA-1350 (HP Compressor Trem 1) | C3: Delta Pressure - Lube Oil Filter|Hi | D3: =_xlfn.CONCAT(B3,C3) -> FRADE-PBA-1350 (HP Compressor Trem 1)Delta Pressure - Lube Oil Filter|Hi | E3: =IFERROR(TRIM(INDEX(_xlfn.TEXTSPLIT(C3,"|"),1,2)),"") -> Hi | F3: 1 | G3: bar | I3: Sensors - Lube Oil System; | L3: =IFERROR(TRIM(INDEX(_xlfn.TEXTSPLIT(Table3[[#This Row],[Name]],"|"),1,2)),"") -> Pre-alarm
A4: Compressor Basic | B4: FRADE-PBA-1350 (HP Compressor Trem 1) | C4: Delta Pressure - Lube Oil Filter|HiHi | D4: =_xlfn.CONCAT(B4,C4) -> FRADE-PBA-1350 (HP Compressor Trem 1)Delta Pressure - Lube Oil Filter|HiHi | E4: =IFERROR(TRIM(INDEX(_xlfn.TEXTSPLIT(C4,"|"),1,2)),"") -> HiHi | G4: bar | I4: Sensors - Lube Oil System; | L4: =IFERROR(TRIM(INDEX(_xlfn.TEXTSPLIT(Table3[[#This Row],[Name]],"|"),1,2)),"")
A5: Compressor Basic | B5: FRADE-PBA-1350 (HP Compressor Trem 1) | C5: Delta Pressure - Lube Oil Filter|Pre-alarm Hi | D5: =_xlfn.CONCAT(B5,C5) -> FRADE-PBA-1350 (HP Compressor Trem 1)Delta Pressure - Lube Oil Filter|Pre-alarm Hi | E5: =IFERROR(TRIM(INDEX(_xlfn.TEXTSPLIT(C5,"|"),1,2)),"") -> Pre-alarm Hi | G5: bar | I5: Sensors - Lube Oil System; | L5: =IFERROR(TRIM(INDEX(_xlfn.TEXTSPLIT(Table3[[#This Row],[Name]],"|"),1,2)),"") -> Hi
A6: Compressor Basic | B6: FRADE-PBA-1350 (HP Compressor Trem 1) | C6: Level - Lube Oil Tank (1) | D6: =_xlfn.CONCAT(B6,C6) -> FRADE-PBA-1350 (HP Compressor Trem 1)Level - Lube Oil Tank (1) | E6: =IFERROR(TRIM(INDEX(_xlfn.TEXTSPLIT(C6,"|"),1,2)),"") | F6: =VLOOKUP(D6,REF!$AA$1:$AB$149,2,0) -> FRTS-LI-1412A | G6: % | H6: Sensors - Lube Oil System; | I6: Sensors - Lube Oil System; | L6: =IFERROR(TRIM(INDEX(_xlfn.TEXTSPLIT(Table3[[#This Row],[Name]],"|"),1,2)),"") -> HiHi
A7: Compressor Basic | B7: FRADE-PBA-1350 (HP Compressor Trem 1) | C7: Level - Lube Oil Tank (1)|Hi | D7: =_xlfn.CONCAT(B7,C7) -> FRADE-PBA-1350 (HP Compressor Trem 1)Level - Lube Oil Tank (1)|Hi | E7: =IFERROR(TRIM(INDEX(_xlfn.TEXTSPLIT(C7,"|"),1,2)),"") -> Hi | G7: % | I7: Sensors - Lube Oil System; | L7: =IFERROR(TRIM(INDEX(_xlfn.TEXTSPLIT(Table3[[#This Row],[Name]],"|"),1,2)),"") -> Pre-alarm Hi
A8: Compressor Basic | B8: FRADE-PBA-1350 (HP Compressor Trem 1) | C8: Level - Lube Oil Tank (1)|HiHi | D8: =_xlfn.CONCAT(B8,C8) -> FRADE-PBA-1350 (HP Compressor Trem 1)Level - Lube Oil Tank (1)|HiHi | E8: =IFERROR(TRIM(INDEX(_xlfn.TEXTSPLIT(C8,"|"),1,2)),"") -> HiHi | G8: % | I8: Sensors - Lube Oil System; | L8: =IFERROR(TRIM(INDEX(_xlfn.TEXTSPLIT(Table3[[#This Row],[Name]],"|"),1,2)),"")
A9: Compressor Basic | B9: FRADE-PBA-1350 (HP Compressor Trem 1) | C9: Level - Lube Oil Tank (1)|Lo | D9: =_xlfn.CONCAT(B9,C9) -> FRADE-PBA-1350 (HP Compressor Trem 1)Level - Lube Oil Tank (1)|Lo | E9: =IFERROR(TRIM(INDEX(_xlfn.TEXTSPLIT(C9,"|"),1,2)),"") -> Lo | G9: % | I9: Sensors - Lube Oil System; | L9: =IFERROR(TRIM(INDEX(_xlfn.TEXTSPLIT(Table3[[#This Row],[Name]],"|"),1,2)),"") -> Hi
A10: Compressor Basic | B10: FRADE-PBA-1350 (HP Compressor Trem 1) | C10: Level - Lube Oil Tank (1)|LoLo | D10: =_xlfn.CONCAT(B10,C10) -> FRADE-PBA-1350 (HP Compressor Trem 1)Level - Lube Oil Tank (1)|LoLo | E10: =IFERROR(TRIM(INDEX(_xlfn.TEXTSPLIT(C10,"|"),1,2)),"") -> LoLo | G10: % | I10: Sensors - Lube Oil System; | L10: =IFERROR(TRIM(INDEX(_xlfn.TEXTSPLIT(Table3[[#This Row],[Name]],"|"),1,2)),"") -> Lo
A11: Compressor Basic | B11: FRADE-PBA-1350 (HP Compressor Trem 1) | C11: Level - Lube Oil Tank (1)|Pre-alarm Hi | D11: =_xlfn.CONCAT(B11,C11) -> FRADE-PBA-1350 (HP Compressor Trem 1)Level - Lube Oil Tank (1)|Pre-alarm Hi | E11: =IFERROR(TRIM(INDEX(_xlfn.TEXTSPLIT(C11,"|"),1,2)),"") -> Pre-alarm Hi | G11: % | I11: Sensors - Lube Oil System; | L11: =IFERROR(TRIM(INDEX(_xlfn.TEXTSPLIT(Table3[[#This Row],[Name]],"|"),1,2)),"")
A12: Compressor Basic | B12: FRADE-PBA-1350 (HP Compressor Trem 1) | C12: Level - Lube Oil Tank (1)|Pre-alarm Lo | D12: =_xlfn.CONCAT(B12,C12) -> FRADE-PBA-1350 (HP Compressor Trem 1)Level - Lube Oil Tank (1)|Pre-alarm Lo | E12: =IFERROR(TRIM(INDEX(_xlfn.TEXTSPLIT(C12,"|"),1,2)),"") -> Pre-alarm Lo | G12: % | I12: Sensors - Lube Oil System; | L12: =IFERROR(TRIM(INDEX(_xlfn.TEXTSPLIT(Table3[[#This Row],[Name]],"|"),1,2)),"") -> Hi
A13: Compressor Basic | B13: FRADE-PBA-1350 (HP Compressor Trem 1) | C13: Level - Lube Oil Tank (2) | D13: =_xlfn.CONCAT(B13,C13) -> FRADE-PBA-1350 (HP Compressor Trem 1)Level - Lube Oil Tank (2) | E13: =IFERROR(TRIM(INDEX(_xlfn.TEXTSPLIT(C13,"|"),1,2)),"") | F13: =VLOOKUP(D13,REF!$AA$1:$AB$149,2,0) -> FRTS-071-LI-1412B | H13: Sensors - Lube Oil System; | I13: Sensors - Lube Oil System; | J13: Não encontrado no PI | L13: =IFERROR(TRIM(INDEX(_xlfn.TEXTSPLIT(Table3[[#This Row],[Name]],"|"),1,2)),"") -> HiHi
A14: Compressor Basic | B14: FRADE-PBA-1350 (HP Compressor Trem 1) | C14: Level - Lube Oil Tank (2)|Hi | D14: =_xlfn.CONCAT(B14,C14) -> FRADE-PBA-1350 (HP Compressor Trem 1)Level - Lube Oil Tank (2)|Hi | E14: =IFERROR(TRIM(INDEX(_xlfn.TEXTSPLIT(C14,"|"),1,2)),"") -> Hi | I14: Sensors - Lube Oil System; | L14: =IFERROR(TRIM(INDEX(_xlfn.TEXTSPLIT(Table3[[#This Row],[Name]],"|"),1,2)),"") -> Lo
A15: Compressor Basic | B15: FRADE-PBA-1350 (HP Compressor Trem 1) | C15: Level - Lube Oil Tank (2)|HiHi | D15: =_xlfn.CONCAT(B15,C15) -> FRADE-PBA-1350 (HP Compressor Trem 1)Level - Lube Oil Tank (2)|HiHi | E15: =IFERROR(TRIM(INDEX(_xlfn.TEXTSPLIT(C15,"|"),1,2)),"") -> HiHi | I15: Sensors - Lube Oil System; | L15: =IFERROR(TRIM(INDEX(_xlfn.TEXTSPLIT(Table3[[#This Row],[Name]],"|"),1,2)),"") -> LoLo
A16: Compressor Basic | B16: FRADE-PBA-1350 (HP Compressor Trem 1) | C16: Level - Lube Oil Tank (2)|Lo | D16: =_xlfn.CONCAT(B16,C16) -> FRADE-PBA-1350 (HP Compressor Trem 1)Level - Lube Oil Tank (2)|Lo | E16: =IFERROR(TRIM(INDEX(_xlfn.TEXTSPLIT(C16,"|"),1,2)),"") -> Lo | I16: Sensors - Lube Oil System; | L16: =IFERROR(TRIM(INDEX(_xlfn.TEXTSPLIT(Table3[[#This Row],[Name]],"|"),1,2)),"") -> Pre-alarm Hi
A17: Compressor Basic | B17: FRADE-PBA-1350 (HP Compressor Trem 1) | C17: Level - Lube Oil Tank (2)|LoLo | D17: =_xlfn.CONCAT(B17,C17) -> FRADE-PBA-1350 (HP Compressor Trem 1)Level - Lube Oil Tank (2)|LoLo | E17: =IFERROR(TRIM(INDEX(_xlfn.TEXTSPLIT(C17,"|"),1,2)),"") -> LoLo | I17: Sensors - Lube Oil System; | L17: =IFERROR(TRIM(INDEX(_xlfn.TEXTSPLIT(Table3[[#This Row],[Name]],"|"),1,2)),"") -> Pre-alarm Lo
A18: Compressor Basic | B18: FRADE-PBA-1350 (HP Compressor Trem 1) | C18: Level - Lube Oil Tank (2)|Pre-alarm Hi | D18: =_xlfn.CONCAT(B18,C18) -> FRADE-PBA-1350 (HP Compressor Trem 1)Level - Lube Oil Tank (2)|Pre-alarm Hi | E18: =IFERROR(TRIM(INDEX(_xlfn.TEXTSPLIT(C18,"|"),1,2)),"") -> Pre-alarm Hi | I18: Sensors - Lube Oil System; | L18: =IFERROR(TRIM(INDEX(_xlfn.TEXTSPLIT(Table3[[#This Row],[Name]],"|"),1,2)),"")
A19: Compressor Basic | B19: FRADE-PBA-1350 (HP Compressor Trem 1) | C19: Level - Lube Oil Tank (2)|Pre-alarm Lo | D19: =_xlfn.CONCAT(B19,C19) -> FRADE-PBA-1350 (HP Compressor Trem 1)Level - Lube Oil Tank (2)|Pre-alarm Lo | E19: =IFERROR(TRIM(INDEX(_xlfn.TEXTSPLIT(C19,"|"),1,2)),"") -> Pre-alarm Lo | I19: Sensors - Lube Oil System; | L19: =IFERROR(TRIM(INDEX(_xlfn.TEXTSPLIT(Table3[[#This Row],[Name]],"|"),1,2)),"") -> Hi
A20: Compressor Basic | B20: FRADE-PBA-1350 (HP Compressor Trem 1) | C20: Level - Rundown Tank | D20: =_xlfn.CONCAT(B20,C20) -> FRADE-PBA-1350 (HP Compressor Trem 1)Level - Rundown Tank | E20: =IFERROR(TRIM(INDEX(_xlfn.TEXTSPLIT(C20,"|"),1,2)),"") | F20: =VLOOKUP(D20,REF!$AA$1:$AB$149,2,0) -> FRTS-071-LT-1428 | H20: Sensors - Lube Oil System; | I20: Sensors - Lube Oil System; | J20: Não encontrado no PI | L20: =IFERROR(TRIM(INDEX(_xlfn.TEXTSPLIT(Table3[[#This Row],[Name]],"|"),1,2)),"") -> HiHi
A21: Compressor Basic | B21: FRADE-PBA-1350 (HP Compressor Trem 1) | C21: Level - Rundown Tank|Hi | D21: =_xlfn.CONCAT(B21,C21) -> FRADE-PBA-1350 (HP Compressor Trem 1)Level - Rundown Tank|Hi | E21: =IFERROR(TRIM(INDEX(_xlfn.TEXTSPLIT(C21,"|"),1,2)),"") -> Hi | I21: Sensors - Lube Oil System; | J21: Não encontrado no PI | L21: =IFERROR(TRIM(INDEX(_xlfn.TEXTSPLIT(Table3[[#This Row],[Name]],"|"),1,2)),"") -> Lo
A22: Compressor Basic | B22: FRADE-PBA-1350 (HP Compressor Trem 1) | C22: Level - Rundown Tank|Lo | D22: =_xlfn.CONCAT(B22,C22) -> FRADE-PBA-1350 (HP Compressor Trem 1)Level - Rundown Tank|Lo | E22: =IFERROR(TRIM(INDEX(_xlfn.TEXTSPLIT(C22,"|"),1,2)),"") -> Lo | I22: Sensors - Lube Oil System; | J22: Não encontrado no PI | L22: =IFERROR(TRIM(INDEX(_xlfn.TEXTSPLIT(Table3[[#This Row],[Name]],"|"),1,2)),"") -> LoLo
A23: Compressor Basic | B23: FRADE-PBA-1350 (HP Compressor Trem 1) | C23: Level - Rundown Tank|LoLo | D23: =_xlfn.CONCAT(B23,C23) -> FRADE-PBA-1350 (HP Compressor Trem 1)Level - Rundown Tank|LoLo | E23: =IFERROR(TRIM(INDEX(_xlfn.TEXTSPLIT(C23,"|"),1,2)),"") -> LoLo | I23: Sensors - Lube Oil System; | J23: Não encontrado no PI | L23: =IFERROR(TRIM(INDEX(_xlfn.TEXTSPLIT(Table3[[#This Row],[Name]],"|"),1,2)),"") -> Pre-alarm Hi
A24: Compressor Basic | B24: FRADE-PBA-1350 (HP Compressor Trem 1) | C24: Level - Rundown Tank|Pre-alarm Lo | D24: =_xlfn.CONCAT(B24,C24) -> FRADE-PBA-1350 (HP Compressor Trem 1)Level - Rundown Tank|Pre-alarm Lo | E24: =IFERROR(TRIM(INDEX(_xlfn.TEXTSPLIT(C24,"|"),1,2)),"") -> Pre-alarm Lo | I24: Sensors - Lube Oil System; | J24: Não encontrado no PI | L24: =IFERROR(TRIM(INDEX(_xlfn.TEXTSPLIT(Table3[[#This Row],[Name]],"|"),1,2)),"") -> Pre-alarm Lo
A25: Compressor Basic | B25: FRADE-PBA-1350 (HP Compressor Trem 1) | C25: Pressure - Lube Oil Bearings Header | D25: =_xlfn.CONCAT(B25,C25) -> FRADE-PBA-1350 (HP Compressor Trem 1)Pressure - Lube Oil Bearings Header | E25: =IFERROR(TRIM(INDEX(_xlfn.TEXTSPLIT(C25,"|"),1,2)),"") | F25: =VLOOKUP(D25,REF!$AA$1:$AB$149,2,0) -> FRTS-071-PIT-1345 | G25: barg | H25: Sensors - Lube Oil System; | I25: Sensors - Lube Oil System; | J25: Não encontrado no PI | L25: =IFERROR(TRIM(INDEX(_xlfn.TEXTSPLIT(Table3[[#This Row],[Name]],"|"),1,2)),"")
A26: Compressor Basic | B26: FRADE-PBA-1350 (HP Compressor Trem 1) | C26: Pressure - Lube Oil Bearings Header|Hi | D26: =_xlfn.CONCAT(B26,C26) -> FRADE-PBA-1350 (HP Compressor Trem 1)Pressure - Lube Oil Bearings Header|Hi | E26: =IFERROR(TRIM(INDEX(_xlfn.TEXTSPLIT(C26,"|"),1,2)),"") -> Hi | F26: 2.5 | G26: barg | I26: Sensors - Lube Oil System; | L26: =IFERROR(TRIM(INDEX(_xlfn.TEXTSPLIT(Table3[[#This Row],[Name]],"|"),1,2)),"") -> Hi
A27: Compressor Basic | B27: FRADE-PBA-1350 (HP Compressor Trem 1) | C27: Pressure - Lube Oil Bearings Header|Lo | D27: =_xlfn.CONCAT(B27,C27) -> FRADE-PBA-1350 (HP Compressor Trem 1)Pressure - Lube Oil Bearings Header|Lo | E27: =IFERROR(TRIM(INDEX(_xlfn.TEXTSPLIT(C27,"|"),1,2)),"") -> Lo | F27: 1.4 | G27: barg | I27: Sensors - Lube Oil System; | L27: =IFERROR(TRIM(INDEX(_xlfn.TEXTSPLIT(Table3[[#This Row],[Name]],"|"),1,2)),"") -> Lo
A28: Compressor Basic | B28: FRADE-PBA-1350 (HP Compressor Trem 1) | C28: Pressure - Lube Oil Bearings Header|LoLo | D28: =_xlfn.CONCAT(B28,C28) -> FRADE-PBA-1350 (HP Compressor Trem 1)Pressure - Lube Oil Bearings Header|LoLo | E28: =IFERROR(TRIM(INDEX(_xlfn.TEXTSPLIT(C28,"|"),1,2)),"") -> LoLo | G28: barg | I28: Sensors - Lube Oil System; | L28: =IFERROR(TRIM(INDEX(_xlfn.TEXTSPLIT(Table3[[#This Row],[Name]],"|"),1,2)),"") -> LoLo
A29: Compressor Basic | B29: FRADE-PBA-1350 (HP Compressor Trem 1) | C29: Pressure - Lube Oil Bearings Header|Pre-alarm Hi | D29: =_xlfn.CONCAT(B29,C29) -> FRADE-PBA-1350 (HP Compressor Trem 1)Pressure - Lube Oil Bearings Header|Pre-alarm Hi | E29: =IFERROR(TRIM(INDEX(_xlfn.TEXTSPLIT(C29,"|"),1,2)),"") -> Pre-alarm Hi | G29: barg | I29: Sensors - Lube Oil System; | L29: =IFERROR(TRIM(INDEX(_xlfn.TEXTSPLIT(Table3[[#This Row],[Name]],"|"),1,2)),"") -> Pre-alarm Lo
A30: Compressor Basic | B30: FRADE-PBA-1350 (HP Compressor Trem 1) | C30: Pressure - Lube Oil Bearings Header|Pre-alarm Lo | D30: =_xlfn.CONCAT(B30,C30) -> FRADE-PBA-1350 (HP Compressor Trem 1)Pressure - Lube Oil Bearings Header|Pre-alarm Lo | E30: =IFERROR(TRIM(INDEX(_xlfn.TEXTSPLIT(C30,"|"),1,2)),"") -> Pre-alarm Lo | G30: barg | I30: Sensors - Lube Oil System; | L30: =IFERROR(TRIM(INDEX(_xlfn.TEXTSPLIT(Table3[[#This Row],[Name]],"|"),1,2)),"")
A31: Compressor Basic | B31: FRADE-PBA-1350 (HP Compressor Trem 1) | C31: Pressure - Lube Oil Bearings Header (2) | D31: =_xlfn.CONCAT(B31,C31) -> FRADE-PBA-1350 (HP Compressor Trem 1)Pressure - Lube Oil Bearings Header (2) | E31: =IFERROR(TRIM(INDEX(_xlfn.TEXTSPLIT(C31,"|"),1,2)),"") | F31: =VLOOKUP(D31,REF!$AA$1:$AB$149,2,0) -> FRTS-PT-1346 | G31: barg | H31: Sensors - Lube Oil System; | I31: Sensors - Lube Oil System; | L31: =IFERROR(TRIM(INDEX(_xlfn.TEXTSPLIT(Table3[[#This Row],[Name]],"|"),1,2)),"")
A32: Compressor Basic | B32: FRADE-PBA-1350 (HP Compressor Trem 1) | C32: Pressure - Lube Oil Bearings Header (2)|Hi | D32: =_xlfn.CONCAT(B32,C32) -> FRADE-PBA-1350 (HP Compressor Trem 1)Pressure - Lube Oil Bearings Header (2)|Hi | E32: =IFERROR(TRIM(INDEX(_xlfn.TEXTSPLIT(C32,"|"),1,2)),"") -> Hi | G32: barg | I32: Sensors - Lube Oil System; | L32: =IFERROR(TRIM(INDEX(_xlfn.TEXTSPLIT(Table3[[#This Row],[Name]],"|"),1,2)),"") -> Assay
A33: Compressor Basic | B33: FRADE-PBA-1350 (HP Compressor Trem 1) | C33: Pressure - Lube Oil Bearings Header (2)|Lo | D33: =_xlfn.CONCAT(B33,C33) -> FRADE-PBA-1350 (HP Compressor Trem 1)Pressure - Lube Oil Bearings Header (2)|Lo | E33: =IFERROR(TRIM(INDEX(_xlfn.TEXTSPLIT(C33,"|"),1,2)),"") -> Lo | G33: barg | I33: Sensors - Lube Oil System; | L33: =IFERROR(TRIM(INDEX(_xlfn.TEXTSPLIT(Table3[[#This Row],[Name]],"|"),1,2)),"") -> Hi
A34: Compressor Basic | B34: FRADE-PBA-1350 (HP Compressor Trem 1) | C34: Pressure - Lube Oil Bearings Header (2)|LoLo | D34: =_xlfn.CONCAT(B34,C34) -> FRADE-PBA-1350 (HP Compressor Trem 1)Pressure - Lube Oil Bearings Header (2)|LoLo | E34: =IFERROR(TRIM(INDEX(_xlfn.TEXTSPLIT(C34,"|"),1,2)),"") -> LoLo | F34: 1.2 | G34: barg | I34: Sensors - Lube Oil System; | L34: =IFERROR(TRIM(INDEX(_xlfn.TEXTSPLIT(Table3[[#This Row],[Name]],"|"),1,2)),"") -> Particle Count - String
A35: Compressor Basic | B35: FRADE-PBA-1350 (HP Compressor Trem 1) | C35: Pressure - Lube Oil Bearings Header (2)|Pre-alarm Hi | D35: =_xlfn.CONCAT(B35,C35) -> FRADE-PBA-1350 (HP Compressor Trem 1)Pressure - Lube Oil Bearings Header (2)|Pre-alarm Hi | E35: =IFERROR(TRIM(INDEX(_xlfn.TEXTSPLIT(C35,"|"),1,2)),"") -> Pre-alarm Hi | G35: barg | I35: Sensors - Lube Oil System; | L35: =IFERROR(TRIM(INDEX(_xlfn.TEXTSPLIT(Table3[[#This Row],[Name]],"|"),1,2)),"") -> Particle Count - String
A36: Compressor Basic | B36: FRADE-PBA-1350 (HP Compressor Trem 1) | C36: Pressure - Lube Oil Bearings Header (2)|Pre-alarm Lo | D36: =_xlfn.CONCAT(B36,C36) -> FRADE-PBA-1350 (HP Compressor Trem 1)Pressure - Lube Oil Bearings Header (2)|Pre-alarm Lo | E36: =IFERROR(TRIM(INDEX(_xlfn.TEXTSPLIT(C36,"|"),1,2)),"") -> Pre-alarm Lo | G36: barg | I36: Sensors - Lube Oil System; | L36: =IFERROR(TRIM(INDEX(_xlfn.TEXTSPLIT(Table3[[#This Row],[Name]],"|"),1,2)),"") -> Replaced
A37: Compressor Basic | B37: FRADE-PBA-1350 (HP Compressor Trem 1) | C37: Temperature - Lube Oil Header | D37: =_xlfn.CONCAT(B37,C37) -> FRADE-PBA-1350 (HP Compressor Trem 1)Temperature - Lube Oil Header | E37: =IFERROR(TRIM(INDEX(_xlfn.TEXTSPLIT(C37,"|"),1,2)),"") | F37: =VLOOKUP(D37,REF!$AA$1:$AB$149,2,0) -> FRTS-072-TI-1423 | G37: °C | H37: Sensors - Lube Oil System; | I37: Sensors - Lube Oil System; | L37: =IFERROR(TRIM(INDEX(_xlfn.TEXTSPLIT(Table3[[#This Row],[Name]],"|"),1,2)),"") -> Type
A38: Compressor Basic | B38: FRADE-PBA-1350 (HP Compressor Trem 1) | C38: Temperature - Lube Oil Header|Hi | D38: =_xlfn.CONCAT(B38,C38) -> FRADE-PBA-1350 (HP Compressor Trem 1)Temperature - Lube Oil Header|Hi | E38: =IFERROR(TRIM(INDEX(_xlfn.TEXTSPLIT(C38,"|"),1,2)),"") -> Hi | F38: 55 | G38: °C | I38: Sensors - Lube Oil System; | L38: =IFERROR(TRIM(INDEX(_xlfn.TEXTSPLIT(Table3[[#This Row],[Name]],"|"),1,2)),"")
A39: Compressor Basic | B39: FRADE-PBA-1350 (HP Compressor Trem 1) | C39: Temperature - Lube Oil Header|HiHi | D39: =_xlfn.CONCAT(B39,C39) -> FRADE-PBA-1350 (HP Compressor Trem 1)Temperature - Lube Oil Header|HiHi | E39: =IFERROR(TRIM(INDEX(_xlfn.TEXTSPLIT(C39,"|"),1,2)),"") -> HiHi | G39: °C | I39: Sensors - Lube Oil System; | L39: =IFERROR(TRIM(INDEX(_xlfn.TEXTSPLIT(Table3[[#This Row],[Name]],"|"),1,2)),"") -> Hi
A40: Compressor Basic | B40: FRADE-PBA-1350 (HP Compressor Trem 1) | C40: Temperature - Lube Oil Header|Lo | D40: =_xlfn.CONCAT(B40,C40) -> FRADE-PBA-1350 (HP Compressor Trem 1)Temperature - Lube Oil Header|Lo | E40: =IFERROR(TRIM(INDEX(_xlfn.TEXTSPLIT(C40,"|"),1,2)),"") -> Lo | F40: 30 | G40: °C | I40: Sensors - Lube Oil System; | L40: =IFERROR(TRIM(INDEX(_xlfn.TEXTSPLIT(Table3[[#This Row],[Name]],"|"),1,2)),"") -> Lo
...

Sheet Template Centrifugal Compressor
A1: Parent | B1: Name | C1: Categories | D1: Categories 2
A2: Compressor Basic | B2: Delta Pressure - ESDVs at the Scrubber Scution Pipe | C2: Sensors - Scrubber; | D2: Sensors - Scrubber;
A3: Compressor Basic | B3: Delta Pressure - ESDVs at the Scrubber Scution Pipe|Pre-alarm | D3: Sensors - Scrubber;
A4: Compressor Basic | B4: Delta Pressure - Lube Oil Filter | C4: Sensors - Lube Oil System; | D4: Sensors - Lube Oil System;
A5: Compressor Basic | B5: Delta Pressure - Lube Oil Filter|Hi | D5: Sensors - Lube Oil System;
A6: Compressor Basic | B6: Delta Pressure - Lube Oil Filter|HiHi | D6: Sensors - Lube Oil System;
A7: Compressor Basic | B7: Delta Pressure - Lube Oil Filter|Pre-alarm Hi | D7: Sensors - Lube Oil System;
A8: Compressor Basic | B8: Delta Pressure - Lube Oil Reservoir Pressure to Atm | C8: Sensors - Lube Oil System; | D8: Sensors - Lube Oil System;
A9: Compressor Basic | B9: Delta Pressure - Lube Oil Reservoir Pressure to Atm|Hi | D9: Sensors - Lube Oil System;
A10: Compressor Basic | B10: Delta Pressure - Lube Oil Reservoir Pressure to Atm|Lo | D10: Sensors - Lube Oil System;
A11: Compressor Basic | B11: Level - Lube Oil Tank (1) | C11: Sensors - Lube Oil System; | D11: Sensors - Lube Oil System;
A12: Compressor Basic | B12: Level - Lube Oil Tank (1)|Hi | D12: Sensors - Lube Oil System;
A13: Compressor Basic | B13: Level - Lube Oil Tank (1)|HiHi | D13: Sensors - Lube Oil System;
A14: Compressor Basic | B14: Level - Lube Oil Tank (1)|Lo | D14: Sensors - Lube Oil System;
A15: Compressor Basic | B15: Level - Lube Oil Tank (1)|LoLo | D15: Sensors - Lube Oil System;
A16: Compressor Basic | B16: Level - Lube Oil Tank (1)|Pre-alarm Hi | D16: Sensors - Lube Oil System;
A17: Compressor Basic | B17: Level - Lube Oil Tank (1)|Pre-alarm Lo | D17: Sensors - Lube Oil System;
A18: Compressor Basic | B18: Level - Lube Oil Tank (2) | C18: Sensors - Lube Oil System; | D18: Sensors - Lube Oil System;
A19: Compressor Basic | B19: Level - Lube Oil Tank (2)|Hi | D19: Sensors - Lube Oil System;
A20: Compressor Basic | B20: Level - Lube Oil Tank (2)|HiHi | D20: Sensors - Lube Oil System;
A21: Compressor Basic | B21: Level - Lube Oil Tank (2)|Lo | D21: Sensors - Lube Oil System;
A22: Compressor Basic | B22: Level - Lube Oil Tank (2)|LoLo | D22: Sensors - Lube Oil System;
A23: Compressor Basic | B23: Level - Lube Oil Tank (2)|Pre-alarm Hi | D23: Sensors - Lube Oil System;
A24: Compressor Basic | B24: Level - Lube Oil Tank (2)|Pre-alarm Lo | D24: Sensors - Lube Oil System;
A25: Compressor Basic | B25: Level - Rundown Tank | C25: Sensors - Lube Oil System; | D25: Sensors - Lube Oil System;
A26: Compressor Basic | B26: Level - Rundown Tank|Hi | D26: Sensors - Lube Oil System;
A27: Compressor Basic | B27: Level - Rundown Tank|Lo | D27: Sensors - Lube Oil System;
A28: Compressor Basic | B28: Level - Rundown Tank|LoLo | D28: Sensors - Lube Oil System;
A29: Compressor Basic | B29: Level - Rundown Tank|Pre-alarm Lo | D29: Sensors - Lube Oil System;
A30: Compressor Basic | B30: Level - Scrubber | C30: Sensors - Scrubber; | D30: Sensors - Scrubber;
A31: Compressor Basic | B31: Level - Scrubber Control | C31: Sensors - Scrubber; | D31: Sensors - Scrubber;
A32: Compressor Basic | B32: Particle Count|Assay | D32: Sensors - Scrubber;
A33: Compressor Basic | B33: Particle Count|Hi | D33: Sensors - Scrubber;
A34: Compressor Basic | B34: Particle Count|Particle Count - String | D34: Sensors - Scrubber;
A35: Compressor Basic | B35: Particle Count|Particle Count - String|Replaced | D35: Sensors - Scrubber;
A36: Compressor Basic | B36: Particle Count|Replaced | D36: Sensors - Scrubber;
A37: Compressor Basic | B37: Particle Count|Type | D37: Sensors - Scrubber;
A38: Compressor Basic | B38: Pressure - Lube Oil Auxiliary Pump Discharge | C38: Sensors - Lube Oil System; | D38: Sensors - Lube Oil System;
A39: Compressor Basic | B39: Pressure - Lube Oil Auxiliary Pump Discharge|Hi | D39: Sensors - Lube Oil System;
A40: Compressor Basic | B40: Pressure - Lube Oil Auxiliary Pump Discharge|Lo | D40: Sensors - Lube Oil System;
...

Sheet Planta
A1: Template | B1: Equipamento | C1: attribute_name | D1: Value | E1: unit_of_measurement | F1: decimal_places | G1: Categories
A2: Plant - No Card KPIs | B2: Plataforma Polvo A | C2: Plataforma Polvo A | D2: Plataforma Polvo A | E2: % | F2: 2 | G2: Plataforma Polvo A

Sheet OnOff
A1: Asset | B1: Attribute | C1: Value | D1: Observações
A2: FORTE-C-UC-123101A-01 (LP/IP Compressor Trem A) | B2: Keyphasor - Compressor | C2: 6000
A3: FORTE-C-UC-123101A-02 (HP Compressor Trem A) | B3: Keyphasor - Compressor | C3: 6000
A4: FORTE-M-UC-123101A (LP/IP/HP Motor Trem A) | B4: Keyphasor - Motor | C4: 500
A5: FORTE-VV-C-UC-123101A (LP/IP/HP Gearbox Trem A) | B5: Keyphasor - Motor | C5: 500 | D5: Está sem dados no Lighthouse, mas a mesma tag tem dados no motor.
A6: FORTE-C-UC-123101B-01 (LP/IP Compressor Trem B) | B6: Keyphasor - Compressor | C6: 6000
A7: FORTE-C-UC-123101B-02 (HP Compressor Trem B) | B7: Keyphasor - Compressor | C7: 6000
A8: FORTE-M-UC-123101B (LP/IP/HP Motor Trem B) | B8: Keyphasor - Motor | C8: 500
A9: FORTE-VV-C-UC-123101B (LP/IP/HP Gearbox Trem B) | B9: Keyphasor - Motor | C9: 500
A10: FORTE-C-UC-123101C-01 (LP/IP Compressor Trem C) | B10: Keyphasor - Compressor | C10: 6000
